Workbook

Sheet Nasıl Doldurulur
A1: HK Kontrol · Veri Toplama Dosyası (v2 · 19.10.2026)
A2: Uygulamaya yüklenecek temel verileri toplar. Personel adları burada yok; admin panelinden eklenir.
A4: Renkler
A5: Mavi yazı: girdiğin veri (değiştirebilirsin). Siyah yazı: formül, dokunma. Sarı hücre: eksik bilgi, doldurulması gerekiyor.
A7: Sayfalar
A8: 1. Oteller: Her tesis bir satır. Bölge İstanbul veya İzmir (süpervizör yetkisi buna göre). Tiny Houses ayrı birim olarak tanımlı.
A9: 2. Oda Tipleri: Her tip bir satır. Kod tüm tesislerde benzersiz. Temizlik süreleri: min (şüpheli kısa) ve max (süre aşımı) dakika; max takibi "Max Süre Aktif = Evet" olan tiplerde çalışır.
A10: 3. Oda Özellikleri: Özellik × oda tipi tablosu (Özellikler.xlsx dosyasından). Evet / boş.
A11: 4. Odalar: Her oda bir satır. Oda tipi kodu açılır listeden.
A12: 5. Kontrol Adımları: Her oda tipi için çekim sırası. Şu an sadece X3 dolu (17 adım); diğer tipler video/foto gelince eklenecek.
A13: 6. Kalem Kataloğu: TESİS BAZINDA tüm demirbaş, mutfak malzemesi, sarf, içecek ve ikram kalemleri. Her kalemin kodu, adı ve fotoğrafı burada. Personel uygulamada kaleme basınca bu fotoğrafı görür.
A14: 7. Envanter - Demirbaş: Oda tipi + kalem + adet (mobilya, tekstil, cihaz, banyo sarfı). Kalem adı ve türü katalogdan formülle gelir.
... A23: Kaynaklar: X3 = 18.10.2026 videosu. Tare Houses X1/X2/X4 = Drive'daki Temmuz 2024 profesyonel çekim fotoğrafları (eski olabilir). Özellikler = Özellikler.xlsx.

Sheet Oteller
A1: Otel Adı | B1: Şehir | C1: Bölge (yetki) | D1: Semt / Adres | E1: Kat Sayısı | F1: Oda Sayısı (otomatik) | G1: PMS'teki Adı (HotelRunner) | H1: Kilit | I1: Not
A2: Tare Houses Hotel | B2: İstanbul | C2: İstanbul | D2: Beşiktaş · Vişnezade Mah., Şair Nedim Cad., Çatlak Çeşme Sok. No:2 | E2: 5 | F2: =COUNTIF(Odalar!A:A,A2) | G2: Tare Houses Hotel | H2: TTLock | I2: Pilot otel.
A3: Tare Suites Beşiktaş | B3: İstanbul | C3: İstanbul | D3: Beşiktaş · Sinanpaşa Mah., Aşık Garip Sok. No:6 | E3: 3 | F3: =COUNTIF(Odalar!A:A,A3) | G3: Tare Suites Beşiktaş | H3: TTLock
A4: Tare Suites Urla | B4: İzmir | C4: İzmir | D4: Urla | E4: 3 | F4: =COUNTIF(Odalar!A:A,A4) | G4: Tare Suites Urla | H4: TTLock | I4: B&B (kahvaltılı) satış sadece burada.
A5: Tare Village Urla | B5: İzmir | C5: İzmir | D5: Urla | E5: 3 | F5: =COUNTIF(Odalar!A:A,A5) | G5: Tare Village Urla | H5: Key-box | I5: PMS'te ayrı otel.
A6: Tiny Houses | B6: İzmir | C6: İzmir | D6: Urla | E6: 1 | F6: =COUNTIF(Odalar!A:A,A6) | G6: Tare Suites Urla | H6: Key-box | I6: Ayrı birim olarak takip edilir. PMS'te Tare Suites Urla altında; uygulamada kendi oteli gibi.

Sheet Oda Tipleri
A1: Oda Tipi Kodu | B1: Oda Tipi Adı | C1: Otel | D1: PMS Kodu | E1: Yaklaşık m² | F1: Yatak Tipi | G1: Maks. Kişi | H1: Mutfak Var mı | I1: Banyo (Duş/Küvet) | J1: Dış Alan | K1: Min. Süre Çıkış (dk) | L1: Min. Süre Konaklama (dk) | M1: Max. Süre Çıkış (dk) | N1: Max. Süre Konaklama (dk) | O1: Max Süre Aktif | P1: Oda Sayısı (otomatik) | Q1: Not
A2: X1 | B2: Deluxe Suite | C2: Tare Houses Hotel | D2: X1 | E2: 35 | F2: King size | G2: 2 | H2: Evet | I2: Duş | J2: Yok | O2: Hayır | P2: =COUNTIF(Odalar!D:D,A2) | Q2: Odalar 101-201-301-401. İsim/m² Özellikler.xlsx sütun sırasından eşlendi (X1→Deluxe Suite); teyit et.
A3: X2 | B3: Deluxe Triple Room | C3: Tare Houses Hotel | D3: X2 | E3: 32 | F3: King size | G3: 2 | H3: Evet | I3: Duş | J3: Yok | O3: Hayır | P3: =COUNTIF(Odalar!D:D,A3) | Q3: Odalar 102-202-302-402. Özellikler.xlsx sırasıyla Deluxe Triple Room; teyit et.
A4: X3 | B4: Deluxe Double Room | C4: Tare Houses Hotel | D4: X3 | E4: 28 | F4: King size | G4: 2 | H4: Evet | I4: Duş | J4: Yok | K4: 25 | L4: 10 | O4: Hayır | P4: =COUNTIF(Odalar!D:D,A4) | Q4: Odalar 103-203-303-403. Mini buzdolabı, 2 göz ocak, evye. Kontrol adımları ve envanter dolu (18.10.2026 videosu).
A5: X4 | B5: Exclusive Suite | C5: Tare Houses Hotel | D5: X4 | E5: 37 | F5: King size | G5: 2 | H5: Evet | I5: Duş | J5: Yok | O5: Hayır | P5: =COUNTIF(Odalar!D:D,A5) | Q5: Odalar 104-204-304-404. Özellikler.xlsx sırasıyla Exclusive Suite; teyit et.
A6: PH | B6: PentHouse Suite | C6: Tare Houses Hotel | D6: PH | E6: 140 | F6: King size | G6: 2 | H6: Evet | I6: Duş+Küvet | J6: Teras | O6: Hayır | P6: =COUNTIF(Odalar!D:D,A6) | Q6: Oda 501. Teras + barbekü, küvet, bornoz, fırın, mikrodalga, kahve makinesi, bulaşık makinesi.
A7: BGS | B7: Garden Suite | C7: Tare Suites Beşiktaş | D7: GS | E7: 50 | F7: King size + Sofa yatak | G7: 4 | H7: Evet | I7: Duş | J7: Balkon, Bahçe | O7: Hayır | P7: =COUNTIF(Odalar!D:D,A7) | Q7: Oda 101. Bahçe + balkon, sofa yatak, kanepe.
A8: BSAB | B8: Studio Apartment with Balcony | C8: Tare Suites Beşiktaş | D8: SAB | E8: 28 | F8: King size | G8: 2 | H8: Evet | I8: Duş | J8: Balkon | O8: Hayır | P8: =COUNTIF(Odalar!D:D,A8) | Q8: Odalar 201, 301. Balkon.
A9: BSA | B9: Studio Apartment | C9: Tare Suites Beşiktaş | D9: SA | E9: 25 | F9: King size | G9: 2 | H9: Evet | I9: Duş | J9: Yok | O9: Hayır | P9: =COUNTIF(Odalar!D:D,A9) | Q9: Odalar 202, 302. Mikrodalga ve çamaşır makinesi var.
A10: EDR | B10: Economy Double Room | C10: Tare Suites Urla | D10: EDR | E10: 14 | F10: Çift kişilik | G10: 2 | H10: Hayır | I10: Duş | J10: Yok | O10: Hayır | P10: =COUNTIF(Odalar!D:D,A10) | Q10: Odalar 101, 102, 202. Mutfak yok, kasa var.
A11: DSSW | B11: Deluxe Suite Sea View | C11: Tare Suites Urla | D11: DSSW | E11: 25 | F11: Çift kişilik | G11: 2 | H11: Hayır | I11: Duş | J11: Yok | O11: Hayır | P11: =COUNTIF(Odalar!D:D,A11) | Q11: Odalar 201, 301. Deniz manzarası, mutfak yok, kasa var.
A12: EXSB | B12: Exclusive Suite with Balcony | C12: Tare Suites Urla | D12: EXSB | E12: 24 | F12: Çift kişilik | G12: 2 | H12: Hayır | I12: Duş | J12: Balkon | O12: Hayır | P12: =COUNTIF(Odalar!D:D,A12) | Q12: Odalar 203, 302. Balkon + deniz manzarası, mutfak yok, kasa var.
A13: DS | B13: Deluxe Suite | C13: Tare Suites Urla | D13: DS | E13: 20 | F13: Çift kişilik | G13: 2 | H13: Hayır | I13: Duş | J13: Yok | O13: Hayır | P13: =COUNTIF(Odalar!D:D,A13) | Q13: Odalar 204, 304. Mutfak yok, kasa var.
A14: DFS | B14: Duplex Family Suite | C14: Tare Suites Urla | D14: DFS | E14: 25 | F14: Çift kişilik | G14: 4 | H14: Hayır | I14: Duş | J14: Yok | O14: Hayır | P14: =COUNTIF(Odalar!D:D,A14) | Q14: Oda 303. Dubleks, mutfak yok, kasa var.
A15: VGS | B15: Garden Suite | C15: Tare Village Urla | D15: GS | E15: 100 | F15: King size + Sofa yatak | G15: 4 | H15: Evet | I15: Duş | J15: Yok | O15: Hayır | P15: =COUNTIF(Odalar!D:D,A15) | Q15: Oda 101 (eski V1). Özellikler.xlsx'te Village tipleri yok.
A16: VBS | B16: Balcony Suite | C16: Tare Village Urla | D16: BS | E16: 40 | F16: King size + Sofa yatak | G16: 4 | H16: Evet | I16: Duş | J16: Balkon | O16: Hayır | P16: =COUNTIF(Odalar!D:D,A16) | Q16: Oda 201 (eski V2). Özellikler.xlsx'te Village tipleri yok.
... A19: TNY | B19: Tiny House | C19: Tiny Houses | D19: Tiny House | E19: 25 | F19: Çift kişilik | G19: 4 | H19: Evet | I19: Duş | J19: Balkon, Teras, Bahçe | O19: Hayır | P19: =COUNTIF(Odalar!D:D,A19) | Q19: T1–T4, tek tip. PMS'te Tare Suites Urla altında; burada ayrı birim. Ocak yok, buzdolabı + kettle var. Engelli erişimi, evcil hayvan dostu, barbekü.
A21: Max Süre Aktif = Evet ise, temizlik bu süreyi aşınca canlı panoda kırmızıya döner ve raporda "süre aşımı" olarak işaretlenir. Hayır ise sadece min. süre (şüpheli kısa) kontrolü çalışır.

Sheet Oda Özellikleri
A1: Kategori | B1: Özellik | C1: X1 | D1: X2 | E1: X3 | F1: X4 | G1: PH | H1: BGS | I1: BSAB | J1: BSA | K1: EDR | L1: DSSW | M1: EXSB | N1: DS | O1: DFS | P1: VGS | Q1: VBS | R1: VSS | S1: VTS | T1: TNY
A2: Genel | B2: Balkon | H2: Evet | I2: Evet | M2: Evet | T2: Evet
A3: Genel | B3: Teras | G3: Evet | T3: Evet
A4: Genel | B4: Bahçe | H4: Evet | T4: Evet
A5: Genel | B5: Oturma Alanı | C5: Evet | D5: Evet | F5: Evet | G5: Evet | H5: Evet | I5: Evet | J5: Evet | L5: Evet | M5: Evet | N5: Evet | O5: Evet | T5: Evet
A6: Genel | B6: Çalışma Masası | C6: Evet | D6: Evet | F6: Evet | G6: Evet | H6: Evet | I6: Evet | J6: Evet | L6: Evet | M6: Evet | N6: Evet | O6: Evet | T6: Evet
A7: Genel | B7: Gardırop | C7: Evet | D7: Evet | E7: Evet | F7: Evet | G7: Evet | H7: Evet | I7: Evet | J7: Evet | K7: Evet | L7: Evet | M7: Evet | N7: Evet | O7: Evet | T7: Evet
A8: Genel | B8: Kanepe | C8: Evet | D8: Evet | H8: Evet
A9: Genel | B9: Klima | C9: Evet | D9: Evet | E9: Evet | F9: Evet | G9: Evet | H9: Evet | I9: Evet | J9: Evet | K9: Evet | L9: Evet | M9: Evet | N9: Evet | O9: Evet | T9: Evet
A10: Genel | B10: Ses Yalıtımı | C10: Evet | D10: Evet | E10: Evet | F10: Evet | G10: Evet | H10: Evet | I10: Evet | J10: Evet | K10: Evet | L10: Evet | M10: Evet | N10: Evet | O10: Evet | T10: Evet
A11: Genel | B11: Barbekü | G11: Evet | T11: Evet
A12: Genel | B12: Engelli Erişimi | T12: Evet
A13: Genel | B13: Sigara İçilebilir(Balkon) | H13: Evet | I13: Evet | M13: Evet | T13: Evet
A14: Genel | B14: Deniz Manzarası | L14: Evet | M14: Evet
A15: Genel | B15: Doğa Manzarası | N15: Evet | O15: Evet | T15: Evet
A16: Genel | B16: Şehir Manzarası | C16: Evet | D16: Evet | E16: Evet | F16: Evet | G16: Evet | H16: Evet | I16: Evet | J16: Evet
A17: Genel | B17: Evcil Hayvan Dostu | T17: Evet
A18: Yatak Tipleri | B18: Tek Kişilik Yatak
A19: Yatak Tipleri | B19: Çift Kişilik Yatak | K19: Evet | L19: Evet | M19: Evet | N19: Evet | O19: Evet | T19: Evet
A20: Yatak Tipleri | B20: King Size Yatak | C20: Evet | D20: Evet | E20: Evet | F20: Evet | G20: Evet | H20: Evet | I20: Evet | J20: Evet
A21: Yatak Tipleri | B21: Sofa Yatak | H21: Evet
A22: Banyo | B22: Özel Banyo | C22: Evet | D22: Evet | E22: Evet | F22: Evet | G22: Evet | H22: Evet | I22: Evet | J22: Evet | K22: Evet | L22: Evet | M22: Evet | N22: Evet | O22: Evet | T22: Evet
A23: Banyo | B23: Duş | C23: Evet | D23: Evet | E23: Evet | F23: Evet | G23: Evet | H23: Evet | I23: Evet | J23: Evet | K23: Evet | L23: Evet | M23: Evet | N23: Evet | O23: Evet | T23: Evet
A24: Banyo | B24: Küvet | G24: Evet
A25: Banyo | B25: Havlu | C25: Evet | D25: Evet | E25: Evet | F25: Evet | G25: Evet | H25: Evet | I25: Evet | J25: Evet | K25: Evet | L25: Evet | M25: Evet | N25: Evet | O25: Evet | T25: Evet
A26: Banyo | B26: Terlik | C26: Evet | D26: Evet | E26: Evet | F26: Evet | G26: Evet | H26: Evet | I26: Evet | J26: Evet | K26: Evet | L26: Evet | M26: Evet | N26: Evet | O26: Evet | T26: Evet
A27: Banyo | B27: Bornoz | G27: Evet
A28: Banyo | B28: Saç Kurutma Makinesi | C28: Evet | D28: Evet | E28: Evet | F28: Evet | G28: Evet | H28: Evet | I28: Evet | J28: Evet | K28: Evet | L28: Evet | M28: Evet | N28: Evet | O28: Evet | T28: Evet
A29: Banyo | B29: Şampuan/Duş Jeli | C29: Evet | D29: Evet | E29: Evet | F29: Evet | G29: Evet | H29: Evet | I29: Evet | J29: Evet | K29: Evet | L29: Evet | M29: Evet | N29: Evet | O29: Evet | T29: Evet
A30: Mutfak | B30: Mutfak | C30: Evet | D30: Evet | E30: Evet | F30: Evet | G30: Evet | H30: Evet | I30: Evet | J30: Evet | T30: Evet
A31: Mutfak | B31: Buzdolabı | C31: Evet | D31: Evet | E31: Evet | F31: Evet | G31: Evet | H31: Evet | I31: Evet | J31: Evet | T31: Evet
A32: Mutfak | B32: Ocak | C32: Evet | D32: Evet | E32: Evet | F32: Evet | G32: Evet | H32: Evet | I32: Evet | J32: Evet
A33: Mutfak | B33: Fırın | G33: Evet
A34: Mutfak | B34: Mikrodalga | G34: Evet | J34: Evet
A35: Mutfak | B35: Su Isıtıcısı | C35: Evet | D35: Evet | E35: Evet | F35: Evet | G35: Evet | H35: Evet | I35: Evet | J35: Evet | K35: Evet | L35: Evet | M35: Evet | N35: Evet | O35: Evet | T35: Evet
A36: Mutfak | B36: Kahve Makinesi | G36: Evet
A37: Mutfak | B37: Temel Mutfak Gereçleri | C37: Evet | D37: Evet | E37: Evet | F37: Evet | G37: Evet | H37: Evet | I37: Evet | J37: Evet | T37: Evet
A38: Mutfak | B38: Tencere&Tava | C38: Evet | D38: Evet | E38: Evet | F38: Evet | G38: Evet | H38: Evet | I38: Evet | J38: Evet | T38: Evet
A39: Mutfak | B39: Bulaşık Makinesi | G39: Evet
A40: Mutfak | B40: Çamaşır Makinesi | J40: Evet
...

Sheet Odalar
A1: Otel | B1: Oda No | C1: Kat | D1: Oda Tipi Kodu | E1: Aktif | F1: Not
A2: Tare Houses Hotel | B2: 101 | C2: 1 | D2: X1 | E2: Evet
A3: Tare Houses Hotel | B3: 102 | C3: 1 | D3: X2 | E3: Evet
A4: Tare Houses Hotel | B4: 103 | C4: 1 | D4: X3 | E4: Evet
A5: Tare Houses Hotel | B5: 104 | C5: 1 | D5: X4 | E5: Evet
A6: Tare Houses Hotel | B6: 201 | C6: 2 | D6: X1 | E6: Evet
A7: Tare Houses Hotel | B7: 202 | C7: 2 | D7: X2 | E7: Evet
A8: Tare Houses Hotel | B8: 203 | C8: 2 | D8: X3 | E8: Evet
A9: Tare Houses Hotel | B9: 204 | C9: 2 | D9: X4 | E9: Evet
A10: Tare Houses Hotel | B10: 301 | C10: 3 | D10: X1 | E10: Evet
A11: Tare Houses Hotel | B11: 302 | C11: 3 | D11: X2 | E11: Evet
A12: Tare Houses Hotel | B12: 303 | C12: 3 | D12: X3 | E12: Evet
A13: Tare Houses Hotel | B13: 304 | C13: 3 | D13: X4 | E13: Evet
... A33: Tare Suites Urla | B33: 304 | C33: 3 | D33: DS | E33: Evet
A34: Tare Village Urla | B34: 101 | C34: 1 | D34: VGS | E34: Evet | F34: Eski kod V1
A35: Tare Village Urla | B35: 201 | C35: 2 | D35: VBS | E35: Evet | F35: Eski kod V2
A36: Tare Village Urla | B36: 202 | C36: 2 | D36: VSS | E36: Evet | F36: Eski kod V3
A37: Tare Village Urla | B37: 301 | C37: 3 | D37: VTS | E37: Evet | F37: Eski kod V4
A38: Tiny Houses | B38: T1 | C38: 1 | D38: TNY | E38: Evet
A39: Tiny Houses | B39: T2 | C39: 1 | D39: TNY | E39: Evet
A40: Tiny Houses | B40: T3 | C40: 1 | D40: TNY | E40: Evet
A41: Tiny Houses | B41: T4 | C41: 1 | D41: TNY | E41: Evet

Sheet Kontrol Adımları
A1: Oda Tipi Kodu | B1: Sıra | C1: Bölge | D1: Adım Adı | E1: Çekim Talimatı | F1: Kontrol Maddeleri (her satır bir madde) | G1: Çıkışta | H1: Konaklamada | I1: Fener Gerekli | J1: Zorunlu | K1: Kare Sayısı | L1: AI Talimatı
A2: X3 | B2: 1 | C2: Giriş | D2: Giriş ve koridor | E2: Kapıdan girip koridoru ve kemeri tek karede çek. Aplikler açık olsun. | F2: Kapı ve şifreli kilit (TTLock) çalışıyor, pil uyarısı yok Süpürgelik ve duvar dipleri tozsuz Koridor aplikleri yanıyor Zeminde leke, saç, kum yok | G2: Evet | H2: Evet | I2: Hayır | J2: Evet
A3: X3 | B3: 2 | C3: Banyo | D3: Lavabo ve tezgah | E3: Lavabo, batarya, ayna ve tezgah altı rafı aynı karede olacak şekilde çek. | F3: Lavabo içi ve gider temiz Batarya parlak, su lekesi yok Sıvı sabun dolu Ayna lekesiz, ışığı yanıyor Raftaki havlular katlı ve tam El havlusu halkada | G3: Evet | H3: Evet | I3: Hayır | J3: Evet
A4: X3 | B4: 3 | C4: Banyo | D4: WC | E4: Klozet kapağı açık, tuvalet kağıdı ve yedek rulo görünecek şekilde çek. | F4: Klozet içi, kapak altı ve dış yüzey temiz Rezervuar paneli parmak izsiz WC fırçası temiz Tuvalet kağıdı takılı + yedek rulo Çöp kovası boş, poşet yeni | G4: Evet | H4: Evet | I4: Hayır | J4: Evet
A5: X3 | B5: 4 | C5: Banyo | D5: Duş | E5: Cam kapıyı ışığa karşı çek (kireç böyle görünür), sonra dispenserleri ve gideri göster. | F5: Cam kapıda kireç ve su lekesi yok Duş seti askıda 3 dispenser dolu Duş sepeti boş Giderde saç yok | G5: Evet | H5: Evet | I5: Hayır | J5: Evet
A6: X3 | B6: 5 | C6: Oda | D6: Gardırop | E6: İki kapağı da aç, askıları ve üst rafı tek karede çek. | F6: Askı sayısı tam Üst rafta yedek battaniye katlı Tabanda unutulmuş eşya yok Alttaki kutu yerinde | G6: Evet | H6: Hayır | I6: Evet | J6: Evet
A7: X3 | B7: 6 | C7: Mutfak | D7: Mutfak tezgahı | E7: Ocak, evye, kettle ve bulaşıklık tek karede olacak şekilde tezgahın karşısından çek. | F7: Ocak camı temiz Evye ve batarya temiz Fırça + sünger temiz Bulaşıklık boş ve kuru Kettle boş, kablosu toplanmış Yağ ve tuz-biber-kürdan dolu Asma çöp kovası boş | G7: Evet | H7: Evet | I7: Hayır | J7: Evet
A8: X3 | B8: 7 | C8: Mutfak | D8: Çekmece 1: çatal-bıçak | E8: Çekmeceyi tamamen aç, feneri aç, tam üstten çek. Çatal-bıçaklar üst üste binmesin. | F8: Çatal, kaşık, bıçak, çay kaşığı tam Şarap açacağı yerinde Setten olmayan parça yok Kaşıklık altı kırıntısız | G8: Evet | H8: Hayır | I8: Evet | J8: Evet
A9: X3 | B9: 8 | C9: Mutfak | D9: Çekmece 2: servis gereçleri | E9: Çekmeceyi tamamen aç, feneri aç, üstten çek. | F9: 4 silikon servis gereci Çekmece içi kırıntısız | G9: Evet | H9: Hayır | I9: Evet | J9: Evet
A10: X3 | B10: 9 | C10: Mutfak | D10: Çekmece 3: bıçak seti | E10: Çekmeceyi tamamen aç, bıçak seti ve kesme tahtası görünsün. | F10: Bıçak seti tam Kesme tahtası temiz | G10: Evet | H10: Hayır | I10: Evet | J10: Evet
A11: X3 | B11: 10 | C11: Mutfak | D11: Üst dolap: bardak ve kupa | E11: Kapağı aç, feneri aç. Bardakları üst üste değil yan yana dizip önden çek. | F11: Kadeh, bardak, kupa sayısı tam Bardaklarda su lekesi yok Kupalarda çay/kahve izi yok | G11: Evet | H11: Hayır | I11: Evet | J11: Evet
A12: X3 | B12: 11 | C12: Mutfak | D12: Evye altı: tencere-tava | E12: Kapağı aç, feneri aç, iki rafı da görecek şekilde çek. | F12: Tava ve tencereler kapaklarıyla tam Tava içi temiz Nihale yerinde Sifonda sızıntı yok | G12: Evet | H12: Hayır | I12: Evet | J12: Evet
A13: X3 | B13: 12 | C13: Mutfak | D13: TV ünitesi alt dolap: tabaklar | E13: İki kapağı da aç. Tabak yığınlarını önden/yandan çek ki tek tek sayılabilsin. | F13: 4'lü tabak ve kase setleri tam Kağıt havlu standı ve rulo var Tabaklarda iz veya çatlak yok | G13: Evet | H13: Hayır | I13: Evet | J13: Evet
... A18: X3 | B18: 17 | C18: Oda | D18: Genel oda | E18: Kapı tarafından tüm odayı tek geniş karede çek. Tüm ışıklar açık. | F18: Klima çalışıyor Oda çöp kovası boş Zemin temiz Duvarda iz/sıyrık yok Tüm aydınlatma yanıyor | G18: Evet | H18: Evet | I18: Hayır | J18: Evet
A19: X1 | B19: 1 | C19: Giriş | D19: Giriş ve kapı | E19: Kapıdan girip girişi ve koridoru tek karede çek. Tüm ışıklar açık olsun. | F19: Kapı ve şifreli kilit çalışıyor Süpürgelik ve duvar dipleri tozsuz Aplikler yanıyor Zeminde leke, saç, kum yok | G19: Evet | H19: Evet | I19: Hayır | K19: 1 | L19: Zeminde görünür kir, saç, çöp var mı? Yanmayan lamba var mı? Konaklama kontrolündeysen misafir eşyalarını değerlendirme.
A20: X1 | B20: 2 | C20: Banyo | D20: Lavabo ve ayna | E20: Lavabo, batarya, ayna ve havlu rafı aynı karede olacak şekilde çek. | F20: Lavabo içi ve gider temiz Batarya parlak, su lekesi yok Sıvı sabun dolu Ayna lekesiz Havlular katlı ve tam | G20: Evet | H20: Evet | I20: Hayır | K20: 1 | L20: Lavaboda kıl, sabun kalıntısı, su lekesi var mı? Aynada leke var mı? Havlular düzgün katlı mı? Konaklama kontrolündeysen misafir eşyalarını değerlendirme.
A21: X1 | B21: 3 | C21: Banyo | D21: WC | E21: Klozet kapağı açık, tuvalet kağıdı ve yedek rulo görünecek şekilde çek. | F21: Klozet içi, kapak altı ve dış yüzey temiz WC fırçası temiz Tuvalet kağıdı takılı + yedek rulo Çöp kovası boş, poşet yeni | G21: Evet | H21: Evet | I21: Hayır | K21: 1 | L21: Klozet içinde veya kapakta leke/kir var mı? Tuvalet kağıdı ve yedek rulo var mı? Çöp kovası boş mu?
A22: X1 | B22: 4 | C22: Banyo | D22: Duş | E22: Duş camını ışığa karşı çek (kireç böyle görünür); dispenserler ve gider görünsün. | F22: Camda kireç ve su lekesi yok Duş seti askıda Şampuan/duş jeli dolu Giderde saç yok | G22: Evet | H22: Evet | I22: Hayır | K22: 1 | L22: Duş camında kireç/su lekesi, giderde saç, zeminde kir var mı? Konaklama kontrolündeysen misafir eşyalarını değerlendirme.
A23: X1 | B23: 5 | C23: Oda | D23: Gardırop | E23: Kapakları aç, askıları ve rafları tek karede çek. İçerisi karanlıksa feneri aç. | F23: Askılar tam Yedek battaniye/yastık katlı Unutulmuş eşya yok | G23: Evet | H23: Hayır | I23: Evet | K23: 1 | L23: Gardıropta unutulmuş eşya, çöp var mı? Askılar düzenli mi?
A24: X1 | B24: 6 | C24: Mutfak | D24: Mutfak tezgahı | E24: Tezgahın karşısından ocak, evye, kettle ve bulaşıklık tek karede olacak şekilde çek. | F24: Ocak temiz Evye ve batarya temiz Sünger ve fırça temiz Bulaşıklık boş ve kuru Kettle boş, kablosu toplanmış Tuz-biber-yağ dolu Çöp kovası boş | G24: Evet | H24: Evet | I24: Hayır | K24: 1 | L24: Tezgahta, ocakta, evyede kir, yağ, kırıntı veya bulaşık var mı? Çöp dolu mu? Konaklama kontrolündeysen misafir eşyalarını değerlendirme.
A25: X1 | B25: 7 | C25: Mutfak | D25: Çekmeceler | E25: Çekmeceleri sırayla aç, feneri aç ve her birini tam üstten çek. | F25: Çatal, kaşık, bıçak tam Servis gereçleri yerinde Çekmece içleri kırıntısız | G25: Evet | H25: Hayır | I25: Evet | K25: 2 | L25: Çekmece içinde kırıntı, kir, yerinden oynamış eşya var mı?
A26: X1 | B26: 8 | C26: Mutfak | D26: Dolaplar: tabak, bardak, tencere | E26: Üst ve alt dolapların kapaklarını aç, feneri aç; tabak, bardak ve tencereler görünsün. | F26: Tabak, kase, bardak, kupa sayısı tam Bardaklarda su lekesi, kupalarda çay/kahve izi yok Tencere ve tavalar temiz, kapaklı Evye altında sızıntı yok | G26: Evet | H26: Hayır | I26: Evet | K26: 2 | L26: Bardaklarda leke, tabaklarda iz/çatlak, tencerelerde yemek kalıntısı var mı?
A27: X1 | B27: 9 | C27: Mutfak | D27: Buzdolabı | E27: Kapağı tamamen aç; içi ve kapak rafları görünsün. | F27: Raflar temiz Unutulmuş yiyecek yok Koku ve buzlanma yok | G27: Evet | H27: Hayır | I27: Hayır | K27: 1 | L27: Buzdolabında yiyecek kalıntısı, leke, buzlanma var mı?
A28: X1 | B28: 10 | C28: Oda | D28: TV ve ünite | E28: TV ve ünite raflarını önden çek. | F28: TV ekranı tozsuz Ünite rafları tozsuz Kumandalar yerinde | G28: Evet | H28: Evet | I28: Hayır | K28: 1 | L28: TV ve raflarda toz, leke var mı? Konaklama kontrolündeysen misafir eşyalarını değerlendirme.
A29: X1 | B29: 11 | C29: Oda | D29: Oturma alanı ve masa | E29: Pencereye doğru geniş açıyla çek; masa, koltuklar ve kanepe görünsün. | F29: Perde ve tül düzgün Masa temiz Koltuk/kanepe temiz, minderler düzgün Sofa yatak toplanmış | G29: Evet | H29: Evet | I29: Hayır | K29: 1 | L29: Masada, koltuklarda kir, leke, unutulmuş eşya var mı? Konaklama kontrolündeysen misafir eşyalarını değerlendirme.
A30: X1 | B30: 12 | C30: Oda | D30: Yatak ve komodinler | E30: Yatağı ayak ucundan tamamı görünecek şekilde çek; ikinci karede yatak altını ve komodinleri çek. | F30: Çarşaf dört köşeden gergin Yastıklar tam, kılıflar lekesiz Yatak altında eşya/toz yok Komodinler boş ve tozsuz | G30: Evet | H30: Evet | I30: Hayır | K30: 2 | L30: Çarşafta kırışık, leke, saç var mı? Yastıklar düzgün mü? Yatak altında eşya/toz var mı? Konaklama kontrolündeysen misafir eşyalarını değerlendirme.
... A245: TNY | B245: 17 | C245: Oda | D245: Genel oda | E245: Kapı tarafından tüm odayı tek geniş karede çek. Tüm ışıklar açık. | F245: Klima çalışıyor Çöp kovaları boş Zemin temiz Duvarda iz yok Tüm aydınlatma yanıyor | G245: Evet | H245: Evet | I245: Hayır | K245: 1 | L245: Zeminde kir, çöp; yanmayan lamba; dağınıklık var mı? Konaklama kontrolündeysen misafir eşyalarını değerlendirme.

Sheet Kalem Kataloğu
A1: Tesis | B1: Kalem Kodu | C1: Kalem Adı | D1: Tür | E1: Tarif (ayırt edici) | F1: Foto Dosyası | G1: Foto Durumu | H1: Kaynak | I1: Not
A2: Tare Houses Hotel | B2: wardrobe_box | C2: Alt kutu (içeriği doğrulanacak) | D2: Demirbaş | G2: Çekilecek | H2: Video 18.10.2026
A3: Tare Houses Hotel | B3: cooktop | C3: Ankastre 2 gözlü cam seramik ocak, Beko | D3: Demirbaş | F3: item_photos/tare_houses/cooktop.jpg | G3: Var | H3: Drive foto 1J3XfhmuP6MEYpl_lG2kgdsk2Z8Rsfo7u
A4: Tare Houses Hotel | B4: wc | C4: Asma klozet, bej/kum mat renk | D4: Demirbaş | F4: item_photos/tare_houses/wc.jpg | G4: Var | H4: Drive foto 176Aiy4gXnqdkXqLiFXPG1py-NxVLLYce
A5: Tare Houses Hotel | B5: hanging_bin | C5: Asma çöp kovası | D5: Demirbaş | F5: item_photos/tare_houses/hanging_bin.jpg | G5: Var | H5: Video 18.10.2026
A6: Tare Houses Hotel | B6: bath_towel | C6: Banyo havlusu | D6: Demirbaş | G6: Çekilecek | H6: Video 18.10.2026
A7: Tare Houses Hotel | B7: bath_bin | C7: Banyo çöp kovası | D7: Demirbaş | F7: item_photos/tare_houses/pedal_bin.jpg | G7: Var | H7: Video 18.10.2026
A8: Tare Houses Hotel | B8: bedside_wall_lamp | C8: Başucu apliği, dikey oval opal | D8: Demirbaş | F8: item_photos/tare_houses/bedside_wall_lamp.jpg | G8: Var | H8: Drive foto 1qqZMbxPxzAY3tiWlJeU5zXJ4FJyKCBzS
A9: Tare Houses Hotel | B9: range_hood | C9: Davlumbaz/aspiratör (üst dolap altında) | D9: Demirbaş | G9: Çekilecek | H9: Drive foto 1FFkoBOtD_TWAwlnOYQPDiPXqnAMV2lbR
A10: Tare Houses Hotel | B10: decor_branches | C10: Dekoratif kuru dal, cam vazoda | D10: Demirbaş | F10: item_photos/tare_houses/decor_branches.jpg | G10: Var | H10: Drive foto 17q0mqTudODHZ96MU-QhDuBn5dZGJSr3p
A11: Tare Houses Hotel | B11: smoke_detector | C11: Duman dedektörü (tavan) | D11: Demirbaş | G11: Çekilecek | H11: Drive foto 1FFkoBOtD_TWAwlnOYQPDiPXqnAMV2lbR
A12: Tare Houses Hotel | B12: dispenser | C12: Duvar dispenseri (şampuan, saç kremi, duş jeli) | D12: Demirbaş | F12: item_photos/tare_houses/shower_dispenser.jpg | G12: Var | H12: Video 18.10.2026
A13: Tare Houses Hotel | B13: shower_basket | C13: Duş sepeti | D13: Demirbaş | G13: Çekilecek | H13: Video 18.10.2026
A14: Tare Houses Hotel | B14: hand_towel | C14: El havlusu | D14: Demirbaş | G14: Çekilecek | H14: Video 18.10.2026
A15: Tare Houses Hotel | B15: hanger | C15: Elbise askısı | D15: Demirbaş | G15: Çekilecek | H15: Video 18.10.2026
A16: Tare Houses Hotel | B16: wardrobe | C16: Gardırop, ahşap, çıtalı kapaklı (TV ünitesiyle birleşik) | D16: Demirbaş | G16: Çekilecek | H16: Drive foto 11rd4F0TCuwx9hu3hZWi60hOjhCx_ZmZJ
A17: Tare Houses Hotel | B17: flush_plate | C17: Gömme rezervuar kumanda paneli, mat siyah çift tuş | D17: Demirbaş | F17: item_photos/tare_houses/flush_plate.jpg | G17: Var | H17: Drive foto 176Aiy4gXnqdkXqLiFXPG1py-NxVLLYce
A18: Tare Houses Hotel | B18: rug_striped | C18: Halı, krem çizgili + kiremit yuvarlak desenli | D18: Demirbaş | F18: item_photos/tare_houses/rug_striped.jpg | G18: Var | H18: Drive foto 16QwrP4dnzdun3aDldvqDTQdKeKNFWyfn
A19: Tare Houses Hotel | B19: towel_bar | C19: Havlu askısı (çubuk), mat siyah | D19: Demirbaş | F19: item_photos/tare_houses/towel_bar.jpg | G19: Var | H19: Drive foto 1CWO16nd8G3iNKOmA8b9EgwJjXPrJnCHm
A20: Tare Houses Hotel | B20: towel_ring | C20: Havlu halkası, mat siyah | D20: Demirbaş | F20: item_photos/tare_houses/towel_ring.jpg | G20: Var | H20: Drive foto 176Aiy4gXnqdkXqLiFXPG1py-NxVLLYce
A21: Tare Houses Hotel | B21: sofa_gray | C21: Kanepe (açılır sofa yatak olabilir), gri kadife | D21: Demirbaş | F21: item_photos/tare_houses/sofa_gray.jpg | G21: Var | H21: Drive foto 16QwrP4dnzdun3aDldvqDTQdKeKNFWyfn
A22: Tare Houses Hotel | B22: kettle | C22: Kettle | D22: Demirbaş | F22: item_photos/tare_houses/kettle.jpg | G22: Var | H22: Video 18.10.2026
A23: Tare Houses Hotel | B23: air_conditioner | C23: Klima iç ünitesi, siyah duvar tipi | D23: Demirbaş | F23: item_photos/tare_houses/air_conditioner.jpg | G23: Var | H23: Drive foto 14VC92YctQ5syDFseOCS7bOidn1pAtrxE
A24: Tare Houses Hotel | B24: armchair | C24: Koltuk | D24: Demirbaş | F24: item_photos/tare_houses/armchair.jpg | G24: Var | H24: Video 18.10.2026
A25: Tare Houses Hotel | B25: nightstand | C25: Komodin | D25: Demirbaş | F25: item_photos/tare_houses/nightstand.jpg | G25: Var | H25: Video 18.10.2026
A26: Tare Houses Hotel | B26: remote | C26: Kumanda (TV + klima) | D26: Demirbaş | G26: Çekilecek | H26: Video 18.10.2026
A27: Tare Houses Hotel | B27: floor_lamp | C27: Lambader, pirinç ayaklı beyaz abajurlu, yan tablalı | D27: Demirbaş | F27: item_photos/tare_houses/floor_lamp.jpg | G27: Var | H27: Drive foto 16QwrP4dnzdun3aDldvqDTQdKeKNFWyfn
A28: Tare Houses Hotel | B28: vanity_unit | C28: Lavabo altı açık raflı ahşap ünite | D28: Demirbaş | F28: item_photos/tare_houses/vanity_unit.jpg | G28: Var | H28: Drive foto 176Aiy4gXnqdkXqLiFXPG1py-NxVLLYce
A29: Tare Houses Hotel | B29: basin_faucet | C29: Lavabo bataryası, mat siyah kuğu boyun | D29: Demirbaş | F29: item_photos/tare_houses/basin_faucet.jpg | G29: Var | H29: Drive foto 1rS9OAXDtSWqHfMKIU_QdvLSU1WPLW-2j
A30: Tare Houses Hotel | B30: globe_table_lamp | C30: Masa/başucu lambası, opal küre + pirinç gövde | D30: Demirbaş | F30: item_photos/tare_houses/globe_table_lamp.jpg | G30: Var | H30: Drive foto 1WEP_jDIwucwzg6uxwakrZL5JQ3wq34tk
A31: Tare Houses Hotel | B31: mini_fridge | C31: Mini buzdolabı, beyaz, tezgah altı | D31: Demirbaş | F31: item_photos/tare_houses/mini_fridge.jpg | G31: Var | H31: Drive foto 1FFkoBOtD_TWAwlnOYQPDiPXqnAMV2lbR
A32: Tare Houses Hotel | B32: room_bin | C32: Oda çöp kovası | D32: Demirbaş | G32: Çekilecek | H32: Video 18.10.2026
A33: Tare Houses Hotel | B33: coffee_table_glass | C33: Orta sehpa, yuvarlak cam tablalı siyah metal | D33: Demirbaş | F33: item_photos/tare_houses/coffee_table_glass.jpg | G33: Var | H33: Drive foto 16QwrP4dnzdun3aDldvqDTQdKeKNFWyfn
A34: Tare Houses Hotel | B34: pendant_lamp | C34: Sarkıt avize, siyah metal disk | D34: Demirbaş | F34: item_photos/tare_houses/pendant_lamp.jpg | G34: Var | H34: Drive foto 14qRyaeW762Tt7lrP6OYjJLumQDBFxCAt
A35: Tare Houses Hotel | B35: tv | C35: TV | D35: Demirbaş | F35: item_photos/tare_houses/tv.jpg | G35: Var | H35: Video 18.10.2026
A36: Tare Houses Hotel | B36: wall_art | C36: Tablo, siyah çerçeveli portre baskı (her odada farklı figür) | D36: Demirbaş | F36: item_photos/tare_houses/wall_art.jpg | G36: Var | H36: Drive foto 1qqZMbxPxzAY3tiWlJeU5zXJ4FJyKCBzS
A37: Tare Houses Hotel | B37: shower_set | C37: Tepe duşlu termostatik duş seti + el duşu, mat siyah | D37: Demirbaş | F37: item_photos/tare_houses/shower_set.jpg | G37: Var | H37: Drive foto 176Aiy4gXnqdkXqLiFXPG1py-NxVLLYce
A38: Tare Houses Hotel | B38: vessel_sink | C38: Tezgah üstü lavabo, traverten taş görünümlü | D38: Demirbaş | F38: item_photos/tare_houses/vessel_sink.jpg | G38: Var | H38: Drive foto 1rS9OAXDtSWqHfMKIU_QdvLSU1WPLW-2j
A39: Tare Houses Hotel | B39: toilet_paper_holder | C39: Tuvalet kağıtlığı, kapaklı mat siyah | D39: Demirbaş | F39: item_photos/tare_houses/toilet_paper_holder.jpg | G39: Var | H39: Drive foto 1J_9i45zMZRnEq7xGQCd53p9mfgJAQ6kF
A40: Tare Houses Hotel | B40: toilet_brush | C40: WC fırçası | D40: Demirbaş | G40: Çekilecek | H40: Video 18.10.2026
...

Sheet Envanter - Demirbaş
A1: Tesis | B1: Oda Tipi Kodu | C1: Adım No | D1: Adım Adı (otomatik) | E1: Kalem Kodu | F1: Kalem Adı (otomatik) | G1: Tür (otomatik) | H1: Olması Gereken Adet | I1: Doğrulandı mı | J1: Kaynak | K1: Not
A2: Tare Houses Hotel | B2: X1 | D2: =IFERROR(INDEX('Kontrol Adımları'!$D:$D,MATCH(1,INDEX(('Kontrol Adımları'!$A$1:$A$400=B2)*('Kontrol Adımları'!$B$1:$B$400=C2),0),0)),"") | E2: cooktop | F2: =IFERROR(INDEX('Kalem Kataloğu'!$C$1:$C$1000,MATCH(1,INDEX(('Kalem Kataloğu'!$A$1:$A$1000=A2)*('Kalem Kataloğu'!$B$1:$B$1000=E2),0),0)),"?") | G2: =IFERROR(INDEX('Kalem Kataloğu'!$D$1:$D$1000,MATCH(1,INDEX(('Kalem Kataloğu'!$A$1:$A$1000=A2)*('Kalem Kataloğu'!$B$1:$B$1000=E2),0),0)),"?") | H2: 1 | I2: Hayır | J2: Drive foto (Tem. 2024) | K2: [güven: yüksek]
A3: Tare Houses Hotel | B3: X1 | D3: =IFERROR(INDEX('Kontrol Adımları'!$D:$D,MATCH(1,INDEX(('Kontrol Adımları'!$A$1:$A$400=B3)*('Kontrol Adımları'!$B$1:$B$400=C3),0),0)),"") | E3: wc | F3: =IFERROR(INDEX('Kalem Kataloğu'!$C$1:$C$1000,MATCH(1,INDEX(('Kalem Kataloğu'!$A$1:$A$1000=A3)*('Kalem Kataloğu'!$B$1:$B$1000=E3),0),0)),"?") | G3: =IFERROR(INDEX('Kalem Kataloğu'!$D$1:$D$1000,MATCH(1,INDEX(('Kalem Kataloğu'!$A$1:$A$1000=A3)*('Kalem Kataloğu'!$B$1:$B$1000=E3),0),0)),"?") | H3: 1 | I3: Hayır | J3: Drive foto (Tem. 2024) | K3: [güven: yüksek]
A4: Tare Houses Hotel | B4: X1 | D4: =IFERROR(INDEX('Kontrol Adımları'!$D:$D,MATCH(1,INDEX(('Kontrol Adımları'!$A$1:$A$400=B4)*('Kontrol Adımları'!$B$1:$B$400=C4),0),0)),"") | E4: hanging_bin | F4: =IFERROR(INDEX('Kalem Kataloğu'!$C$1:$C$1000,MATCH(1,INDEX(('Kalem Kataloğu'!$A$1:$A$1000=A4)*('Kalem Kataloğu'!$B$1:$B$1000=E4),0),0)),"?") | G4: =IFERROR(INDEX('Kalem Kataloğu'!$D$1:$D$1000,MATCH(1,INDEX(('Kalem Kataloğu'!$A$1:$A$1000=A4)*('Kalem Kataloğu'!$B$1:$B$1000=E4),0),0)),"?") | H4: 1 | I4: Hayır | J4: Drive foto (Tem. 2024) | K4: [güven: yüksek]
A5: Tare Houses Hotel | B5: X1 | D5: =IFERROR(INDEX('Kontrol Adımları'!$D:$D,MATCH(1,INDEX(('Kontrol Adımları'!$A$1:$A$400=B5)*('Kontrol Adımları'!$B$1:$B$400=C5),0),0)),"") | E5: bath_bin | F5: =IFERROR(INDEX('Kalem Kataloğu'!$C$1:$C$1000,MATCH(1,INDEX(('Kalem Kataloğu'!$A$1:$A$1000=A5)*('Kalem Kataloğu'!$B$1:$B$1000=E5),0),0)),"?") | G5: =IFERROR(INDEX('Kalem Kataloğu'!$D$1:$D$1000,MATCH(1,INDEX(('Kalem Kataloğu'!$A$1:$A$1000=A5)*('Kalem Kataloğu'!$B$1:$B$1000=E5),0),0)),"?") | H5: 1 | I5: Hayır | J5: Drive foto (Tem. 2024) | K5: Excel X3: banyo çöp kovası 1. [güven: yüksek]
A6: Tare Houses Hotel | B6: X1 | D6: =IFERROR(INDEX('Kontrol Adımları'!$D:$D,MATCH(1,INDEX(('Kontrol Adımları'!$A$1:$A$400=B6)*('Kontrol Adımları'!$B$1:$B$400=C6),0),0)),"") | E6: bedside_wall_lamp | F6: =IFERROR(INDEX('Kalem Kataloğu'!$C$1:$C$1000,MATCH(1,INDEX(('Kalem Kataloğu'!$A$1:$A$1000=A6)*('Kalem Kataloğu'!$B$1:$B$1000=E6),0),0)),"?") | G6: =IFERROR(INDEX('Kalem Kataloğu'!$D$1:$D$1000,MATCH(1,INDEX(('Kalem Kataloğu'!$A$1:$A$1000=A6)*('Kalem Kataloğu'!$B$1:$B$1000=E6),0),0)),"?") | H6: 2 | I6: Hayır | J6: Drive foto (Tem. 2024) | K6: Yatağın iki yanında. [güven: orta]
A7: Tare Houses Hotel | B7: X1 | D7: =IFERROR(INDEX('Kontrol Adımları'!$D:$D,MATCH(1,INDEX(('Kontrol Adımları'!$A$1:$A$400=B7)*('Kontrol Adımları'!$B$1:$B$400=C7),0),0)),"") | E7: range_hood | F7: =IFERROR(INDEX('Kalem Kataloğu'!$C$1:$C$1000,MATCH(1,INDEX(('Kalem Kataloğu'!$A$1:$A$1000=A7)*('Kalem Kataloğu'!$B$1:$B$1000=E7),0),0)),"?") | G7: =IFERROR(INDEX('Kalem Kataloğu'!$D$1:$D$1000,MATCH(1,INDEX(('Kalem Kataloğu'!$A$1:$A$1000=A7)*('Kalem Kataloğu'!$B$1:$B$1000=E7),0),0)),"?") | H7: 1 | I7: Hayır | J7: Drive foto (Tem. 2024) | K7: [güven: orta]
A8: Tare Houses Hotel | B8: X1 | D8: =IFERROR(INDEX('Kontrol Adımları'!$D:$D,MATCH(1,INDEX(('Kontrol Adımları'!$A$1:$A$400=B8)*('Kontrol Adımları'!$B$1:$B$400=C8),0),0)),"") | E8: decor_branches | F8: =IFERROR(INDEX('Kalem Kataloğu'!$C$1:$C$1000,MATCH(1,INDEX(('Kalem Kataloğu'!$A$1:$A$1000=A8)*('Kalem Kataloğu'!$B$1:$B$1000=E8),0),0)),"?") | G8: =IFERROR(INDEX('Kalem Kataloğu'!$D$1:$D$1000,MATCH(1,INDEX(('Kalem Kataloğu'!$A$1:$A$1000=A8)*('Kalem Kataloğu'!$B$1:$B$1000=E8),0),0)),"?") | H8: 1 | I8: Hayır | J8: Drive foto (Tem. 2024) | K8: [güven: orta]
A9: Tare Houses Hotel | B9: X1 | D9: =IFERROR(INDEX('Kontrol Adımları'!$D:$D,MATCH(1,INDEX(('Kontrol Adımları'!$A$1:$A$400=B9)*('Kontrol Adımları'!$B$1:$B$400=C9),0),0)),"") | E9: smoke_detector | F9: =IFERROR(INDEX('Kalem Kataloğu'!$C$1:$C$1000,MATCH(1,INDEX(('Kalem Kataloğu'!$A$1:$A$1000=A9)*('Kalem Kataloğu'!$B$1:$B$1000=E9),0),0)),"?") | G9: =IFERROR(INDEX('Kalem Kataloğu'!$D$1:$D$1000,MATCH(1,INDEX(('Kalem Kataloğu'!$A$1:$A$1000=A9)*('Kalem Kataloğu'!$B$1:$B$1000=E9),0),0)),"?") | H9: 1 | I9: Hayır | J9: Drive foto (Tem. 2024) | K9: [güven: orta]
A10: Tare Houses Hotel | B10: X1 | D10: =IFERROR(INDEX('Kontrol Adımları'!$D:$D,MATCH(1,INDEX(('Kontrol Adımları'!$A$1:$A$400=B10)*('Kontrol Adımları'!$B$1:$B$400=C10),0),0)),"") | E10: dispenser | F10: =IFERROR(INDEX('Kalem Kataloğu'!$C$1:$C$1000,MATCH(1,INDEX(('Kalem Kataloğu'!$A$1:$A$1000=A10)*('Kalem Kataloğu'!$B$1:$B$1000=E10),0),0)),"?") | G10: =IFERROR(INDEX('Kalem Kataloğu'!$D$1:$D$1000,MATCH(1,INDEX(('Kalem Kataloğu'!$A$1:$A$1000=A10)*('Kalem Kataloğu'!$B$1:$B$1000=E10),0),0)),"?") | H10: 1 | I10: Hayır | J10: Drive foto (Tem. 2024) | K10: Excel X3: 3 hazne. [güven: yüksek]
A11: Tare Houses Hotel | B11: X1 | D11: =IFERROR(INDEX('Kontrol Adımları'!$D:$D,MATCH(1,INDEX(('Kontrol Adımları'!$A$1:$A$400=B11)*('Kontrol Adımları'!$B$1:$B$400=C11),0),0)),"") | E11: wardrobe | F11: =IFERROR(INDEX('Kalem Kataloğu'!$C$1:$C$1000,MATCH(1,INDEX(('Kalem Kataloğu'!$A$1:$A$1000=A11)*('Kalem Kataloğu'!$B$1:$B$1000=E11),0),0)),"?") | G11: =IFERROR(INDEX('Kalem Kataloğu'!$D$1:$D$1000,MATCH(1,INDEX(('Kalem Kataloğu'!$A$1:$A$1000=A11)*('Kalem Kataloğu'!$B$1:$B$1000=E11),0),0)),"?") | H11: 1 | I11: Hayır | J11: Drive foto (Tem. 2024) | K11: İçi (askı, battaniye) fotoğrafta görünmüyor. Excel X3: askı 6, yedek battaniye 1. [güven: yüksek]
A12: Tare Houses Hotel | B12: X1 | D12: =IFERROR(INDEX('Kontrol Adımları'!$D:$D,MATCH(1,INDEX(('Kontrol Adımları'!$A$1:$A$400=B12)*('Kontrol Adımları'!$B$1:$B$400=C12),0),0)),"") | E12: flush_plate | F12: =IFERROR(INDEX('Kalem Kataloğu'!$C$1:$C$1000,MATCH(1,INDEX(('Kalem Kataloğu'!$A$1:$A$1000=A12)*('Kalem Kataloğu'!$B$1:$B$1000=E12),0),0)),"?") | G12: =IFERROR(INDEX('Kalem Kataloğu'!$D$1:$D$1000,MATCH(1,INDEX(('Kalem Kataloğu'!$A$1:$A$1000=A12)*('Kalem Kataloğu'!$B$1:$B$1000=E12),0),0)),"?") | H12: 1 | I12: Hayır | J12: Drive foto (Tem. 2024) | K12: [güven: yüksek]
A13: Tare Houses Hotel | B13: X1 | D13: =IFERROR(INDEX('Kontrol Adımları'!$D:$D,MATCH(1,INDEX(('Kontrol Adımları'!$A$1:$A$400=B13)*('Kontrol Adımları'!$B$1:$B$400=C13),0),0)),"") | E13: rug_striped | F13: =IFERROR(INDEX('Kalem Kataloğu'!$C$1:$C$1000,MATCH(1,INDEX(('Kalem Kataloğu'!$A$1:$A$1000=A13)*('Kalem Kataloğu'!$B$1:$B$1000=E13),0),0)),"?") | G13: =IFERROR(INDEX('Kalem Kataloğu'!$D$1:$D$1000,MATCH(1,INDEX(('Kalem Kataloğu'!$A$1:$A$1000=A13)*('Kalem Kataloğu'!$B$1:$B$1000=E13),0),0)),"?") | H13: 1 | I13: Hayır | J13: Drive foto (Tem. 2024) | K13: [güven: orta]
... A23: Tare Houses Hotel | B23: X1 | D23: =IFERROR(INDEX('Kontrol Adımları'!$D:$D,MATCH(1,INDEX(('Kontrol Adımları'!$A$1:$A$400=B23)*('Kontrol Adımları'!$B$1:$B$400=C23),0),0)),"") | E23: basin_faucet | F23: =IFERROR(INDEX('Kalem Kataloğu'!$C$1:$C$1000,MATCH(1,INDEX(('Kalem Kataloğu'!$A$1:$A$1000=A23)*('Kalem Kataloğu'!$B$1:$B$1000=E23),0),0)),"?") | G23: =IFERROR(INDEX('Kalem Kataloğu'!$D$1:$D$1000,MATCH(1,INDEX(('Kalem Kataloğu'!$A$1:$A$1000=A23)*('Kalem Kataloğu'!$B$1:$B$1000=E23),0),0)),"?") | H23: 1 | I23: Hayır | J23: Drive foto (Tem. 2024) | K23: [güven: yüksek]
A24: Tare Houses Hotel | B24: X1 | D24: =IFERROR(INDEX('Kontrol Adımları'!$D:$D,MATCH(1,INDEX(('Kontrol Adımları'!$A$1:$A$400=B24)*('Kontrol Adımları'!$B$1:$B$400=C24),0),0)),"") | E24: globe_table_lamp | F24: =IFERROR(INDEX('Kalem Kataloğu'!$C$1:$C$1000,MATCH(1,INDEX(('Kalem Kataloğu'!$A$1:$A$1000=A24)*('Kalem Kataloğu'!$B$1:$B$1000=E24),0),0)),"?") | G24: =IFERROR(INDEX('Kalem Kataloğu'!$D$1:$D$1000,MATCH(1,INDEX(('Kalem Kataloğu'!$A$1:$A$1000=A24)*('Kalem Kataloğu'!$B$1:$B$1000=E24),0),0)),"?") | I24: Hayır | J24: Drive foto (Tem. 2024) | K24: X4 yatak başlığı tablalarında 2 adet. [güven: yüksek]
A25: Tare Houses Hotel | B25: X1 | D25: =IFERROR(INDEX('Kontrol Adımları'!$D:$D,MATCH(1,INDEX(('Kontrol Adımları'!$A$1:$A$400=B25)*('Kontrol Adımları'!$B$1:$B$400=C25),0),0)),"") | E25: mini_fridge | F25: =IFERROR(INDEX('Kalem Kataloğu'!$C$1:$C$1000,MATCH(1,INDEX(('Kalem Kataloğu'!$A$1:$A$1000=A25)*('Kalem Kataloğu'!$B$1:$B$1000=E25),0),0)),"?") | G25: =IFERROR(INDEX('Kalem Kataloğu'!$D$1:$D$1000,MATCH(1,INDEX(('Kalem Kataloğu'!$A$1:$A$1000=A25)*('Kalem Kataloğu'!$B$1:$B$1000=E25),0),0)),"?") | H25: 1 | I25: Hayır | J25: Drive foto (Tem. 2024) | K25: [güven: yüksek]
A26: Tare Houses Hotel | B26: X1 | D26: =IFERROR(INDEX('Kontrol Adımları'!$D:$D,MATCH(1,INDEX(('Kontrol Adımları'!$A$1:$A$400=B26)*('Kontrol Adımları'!$B$1:$B$400=C26),0),0)),"") | E26: coffee_table_glass | F26: =IFERROR(INDEX('Kalem Kataloğu'!$C$1:$C$1000,MATCH(1,INDEX(('Kalem Kataloğu'!$A$1:$A$1000=A26)*('Kalem Kataloğu'!$B$1:$B$1000=E26),0),0)),"?") | G26: =IFERROR(INDEX('Kalem Kataloğu'!$D$1:$D$1000,MATCH(1,INDEX(('Kalem Kataloğu'!$A$1:$A$1000=A26)*('Kalem Kataloğu'!$B$1:$B$1000=E26),0),0)),"?") | H26: 1 | I26: Hayır | J26: Drive foto (Tem. 2024) | K26: [güven: yüksek]
A27: Tare Houses Hotel | B27: X1 | D27: =IFERROR(INDEX('Kontrol Adımları'!$D:$D,MATCH(1,INDEX(('Kontrol Adımları'!$A$1:$A$400=B27)*('Kontrol Adımları'!$B$1:$B$400=C27),0),0)),"") | E27: pendant_lamp | F27: =IFERROR(INDEX('Kalem Kataloğu'!$C$1:$C$1000,MATCH(1,INDEX(('Kalem Kataloğu'!$A$1:$A$1000=A27)*('Kalem Kataloğu'!$B$1:$B$1000=E27),0),0)),"?") | G27: =IFERROR(INDEX('Kalem Kataloğu'!$D$1:$D$1000,MATCH(1,INDEX(('Kalem Kataloğu'!$A$1:$A$1000=A27)*('Kalem Kataloğu'!$B$1:$B$1000=E27),0),0)),"?") | I27: Hayır | J27: Drive foto (Tem. 2024) | K27: [güven: yüksek]
A28: Tare Houses Hotel | B28: X1 | D28: =IFERROR(INDEX('Kontrol Adımları'!$D:$D,MATCH(1,INDEX(('Kontrol Adımları'!$A$1:$A$400=B28)*('Kontrol Adımları'!$B$1:$B$400=C28),0),0)),"") | E28: tv | F28: =IFERROR(INDEX('Kalem Kataloğu'!$C$1:$C$1000,MATCH(1,INDEX(('Kalem Kataloğu'!$A$1:$A$1000=A28)*('Kalem Kataloğu'!$B$1:$B$1000=E28),0),0)),"?") | G28: =IFERROR(INDEX('Kalem Kataloğu'!$D$1:$D$1000,MATCH(1,INDEX(('Kalem Kataloğu'!$A$1:$A$1000=A28)*('Kalem Kataloğu'!$B$1:$B$1000=E28),0),0)),"?") | H28: 2 | I28: Hayır | J28: Drive foto (Tem. 2024) | K28: X1'de yatak odasında 1 + oturma alanı/koridor duvarında 1 görünüyor; teyit et. Excel X3: 1. [güven: orta]
A29: Tare Houses Hotel | B29: X1 | D29: =IFERROR(INDEX('Kontrol Adımları'!$D:$D,MATCH(1,INDEX(('Kontrol Adımları'!$A$1:$A$400=B29)*('Kontrol Adımları'!$B$1:$B$400=C29),0),0)),"") | E29: wall_art | F29: =IFERROR(INDEX('Kalem Kataloğu'!$C$1:$C$1000,MATCH(1,INDEX(('Kalem Kataloğu'!$A$1:$A$1000=A29)*('Kalem Kataloğu'!$B$1:$B$1000=E29),0),0)),"?") | G29: =IFERROR(INDEX('Kalem Kataloğu'!$D$1:$D$1000,MATCH(1,INDEX(('Kalem Kataloğu'!$A$1:$A$1000=A29)*('Kalem Kataloğu'!$B$1:$B$1000=E29),0),0)),"?") | H29: 2 | I29: Hayır | J29: Drive foto (Tem. 2024) | K29: X1: oturma alanı + yatak odası 2 adet. [güven: yüksek]
A30: Tare Houses Hotel | B30: X1 | D30: =IFERROR(INDEX('Kontrol Adımları'!$D:$D,MATCH(1,INDEX(('Kontrol Adımları'!$A$1:$A$400=B30)*('Kontrol Adımları'!$B$1:$B$400=C30),0),0)),"") | E30: shower_set | F30: =IFERROR(INDEX('Kalem Kataloğu'!$C$1:$C$1000,MATCH(1,INDEX(('Kalem Kataloğu'!$A$1:$A$1000=A30)*('Kalem Kataloğu'!$B$1:$B$1000=E30),0),0)),"?") | G30: =IFERROR(INDEX('Kalem Kataloğu'!$D$1:$D$1000,MATCH(1,INDEX(('Kalem Kataloğu'!$A$1:$A$1000=A30)*('Kalem Kataloğu'!$B$1:$B$1000=E30),0),0)),"?") | H30: 1 | I30: Hayır | J30: Drive foto (Tem. 2024) | K30: [güven: yüksek]
A31: Tare Houses Hotel | B31: X1 | D31: =IFERROR(INDEX('Kontrol Adımları'!$D:$D,MATCH(1,INDEX(('Kontrol Adımları'!$A$1:$A$400=B31)*('Kontrol Adımları'!$B$1:$B$400=C31),0),0)),"") | E31: vessel_sink | F31: =IFERROR(INDEX('Kalem Kataloğu'!$C$1:$C$1000,MATCH(1,INDEX(('Kalem Kataloğu'!$A$1:$A$1000=A31)*('Kalem Kataloğu'!$B$1:$B$1000=E31),0),0)),"?") | G31: =IFERROR(INDEX('Kalem Kataloğu'!$D$1:$D$1000,MATCH(1,INDEX(('Kalem Kataloğu'!$A$1:$A$1000=A31)*('Kalem Kataloğu'!$B$1:$B$1000=E31),0),0)),"?") | H31: 1 | I31: Hayır | J31: Drive foto (Tem. 2024) | K31: [güven: yüksek]
A32: Tare Houses Hotel | B32: X1 | D32: =IFERROR(INDEX('Kontrol Adımları'!$D:$D,MATCH(1,INDEX(('Kontrol Adımları'!$A$1:$A$400=B32)*('Kontrol Adımları'!$B$1:$B$400=C32),0),0)),"") | E32: toilet_paper_holder | F32: =IFERROR(INDEX('Kalem Kataloğu'!$C$1:$C$1000,MATCH(1,INDEX(('Kalem Kataloğu'!$A$1:$A$1000=A32)*('Kalem Kataloğu'!$B$1:$B$1000=E32),0),0)),"?") | G32: =IFERROR(INDEX('Kalem Kataloğu'!$D$1:$D$1000,MATCH(1,INDEX(('Kalem Kataloğu'!$A$1:$A$1000=A32)*('Kalem Kataloğu'!$B$1:$B$1000=E32),0),0)),"?") | H32: 1 | I32: Hayır | J32: Drive foto (Tem. 2024) | K32: [güven: orta]
A33: Tare Houses Hotel | B33: X1 | D33: =IFERROR(INDEX('Kontrol Adımları'!$D:$D,MATCH(1,INDEX(('Kontrol Adımları'!$A$1:$A$400=B33)*('Kontrol Adımları'!$B$1:$B$400=C33),0),0)),"") | E33: toilet_brush | F33: =IFERROR(INDEX('Kalem Kataloğu'!$C$1:$C$1000,MATCH(1,INDEX(('Kalem Kataloğu'!$A$1:$A$1000=A33)*('Kalem Kataloğu'!$B$1:$B$1000=E33),0),0)),"?") | G33: =IFERROR(INDEX('Kalem Kataloğu'!$D$1:$D$1000,MATCH(1,INDEX(('Kalem Kataloğu'!$A$1:$A$1000=A33)*('Kalem Kataloğu'!$B$1:$B$1000=E33),0),0)),"?") | H33: 1 | I33: Hayır | J33: Drive foto (Tem. 2024) | K33: Fotoğrafta küçük görünüyor; kırpılmadı. [güven: orta]
A34: Tare Houses Hotel | B34: X1 | D34: =IFERROR(INDEX('Kontrol Adımları'!$D:$D,MATCH(1,INDEX(('Kontrol Adımları'!$A$1:$A$400=B34)*('Kontrol Adımları'!$B$1:$B$400=C34),0),0)),"") | E34: pillow | F34: =IFERROR(INDEX('Kalem Kataloğu'!$C$1:$C$1000,MATCH(1,INDEX(('Kalem Kataloğu'!$A$1:$A$1000=A34)*('Kalem Kataloğu'!$B$1:$B$1000=E34),0),0)),"?") | G34: =IFERROR(INDEX('Kalem Kataloğu'!$D$1:$D$1000,MATCH(1,INDEX(('Kalem Kataloğu'!$A$1:$A$1000=A34)*('Kalem Kataloğu'!$B$1:$B$1000=E34),0),0)),"?") | H34: 4 | I34: Hayır | J34: Drive foto (Tem. 2024) | K34: Yatakta 2 arka + 2 ön. Excel X3: 4 (doğrulanmadı). [güven: orta]
A35: Tare Houses Hotel | B35: X1 | D35: =IFERROR(INDEX('Kontrol Adımları'!$D:$D,MATCH(1,INDEX(('Kontrol Adımları'!$A$1:$A$400=B35)*('Kontrol Adımları'!$B$1:$B$400=C35),0),0)),"") | E35: led_mirror | F35: =IFERROR(INDEX('Kalem Kataloğu'!$C$1:$C$1000,MATCH(1,INDEX(('Kalem Kataloğu'!$A$1:$A$1000=A35)*('Kalem Kataloğu'!$B$1:$B$1000=E35),0),0)),"?") | G35: =IFERROR(INDEX('Kalem Kataloğu'!$D$1:$D$1000,MATCH(1,INDEX(('Kalem Kataloğu'!$A$1:$A$1000=A35)*('Kalem Kataloğu'!$B$1:$B$1000=E35),0),0)),"?") | H35: 1 | I35: Hayır | J35: Drive foto (Tem. 2024) | K35: [güven: yüksek]
A36: Tare Houses Hotel | B36: X1 | D36: =IFERROR(INDEX('Kontrol Adımları'!$D:$D,MATCH(1,INDEX(('Kontrol Adımları'!$A$1:$A$400=B36)*('Kontrol Adımları'!$B$1:$B$400=C36),0),0)),"") | E36: round_wall_lamp | F36: =IFERROR(INDEX('Kalem Kataloğu'!$C$1:$C$1000,MATCH(1,INDEX(('Kalem Kataloğu'!$A$1:$A$1000=A36)*('Kalem Kataloğu'!$B$1:$B$1000=E36),0),0)),"?") | G36: =IFERROR(INDEX('Kalem Kataloğu'!$D$1:$D$1000,MATCH(1,INDEX(('Kalem Kataloğu'!$A$1:$A$1000=A36)*('Kalem Kataloğu'!$B$1:$B$1000=E36),0),0)),"?") | I36: Hayır | J36: Drive foto (Tem. 2024) | K36: Odalarda 1-3 adet; tip bazında sayılmalı. [güven: orta]
A37: Tare Houses Hotel | B37: X1 | D37: =IFERROR(INDEX('Kontrol Adımları'!$D:$D,MATCH(1,INDEX(('Kontrol Adımları'!$A$1:$A$400=B37)*('Kontrol Adımları'!$B$1:$B$400=C37),0),0)),"") | E37: round_rug_woven | F37: =IFERROR(INDEX('Kalem Kataloğu'!$C$1:$C$1000,MATCH(1,INDEX(('Kalem Kataloğu'!$A$1:$A$1000=A37)*('Kalem Kataloğu'!$B$1:$B$1000=E37),0),0)),"?") | G37: =IFERROR(INDEX('Kalem Kataloğu'!$D$1:$D$1000,MATCH(1,INDEX(('Kalem Kataloğu'!$A$1:$A$1000=A37)*('Kalem Kataloğu'!$B$1:$B$1000=E37),0),0)),"?") | I37: Hayır | J37: Drive foto (Tem. 2024) | K37: [güven: yüksek]
A38: Tare Houses Hotel | B38: X1 | D38: =IFERROR(INDEX('Kontrol Adımları'!$D:$D,MATCH(1,INDEX(('Kontrol Adımları'!$A$1:$A$400=B38)*('Kontrol Adımları'!$B$1:$B$400=C38),0),0)),"") | E38: round_table | F38: =IFERROR(INDEX('Kalem Kataloğu'!$C$1:$C$1000,MATCH(1,INDEX(('Kalem Kataloğu'!$A$1:$A$1000=A38)*('Kalem Kataloğu'!$B$1:$B$1000=E38),0),0)),"?") | G38: =IFERROR(INDEX('Kalem Kataloğu'!$D$1:$D$1000,MATCH(1,INDEX(('Kalem Kataloğu'!$A$1:$A$1000=A38)*('Kalem Kataloğu'!$B$1:$B$1000=E38),0),0)),"?") | I38: Hayır | J38: Drive foto (Tem. 2024) | K38: X1'de yuvarlak masa yerine çalışma masası var. [güven: yüksek]
A39: Tare Houses Hotel | B39: X1 | D39: =IFERROR(INDEX('Kontrol Adımları'!$D:$D,MATCH(1,INDEX(('Kontrol Adımları'!$A$1:$A$400=B39)*('Kontrol Adımları'!$B$1:$B$400=C39),0),0)),"") | E39: round_bed | F39: =IFERROR(INDEX('Kalem Kataloğu'!$C$1:$C$1000,MATCH(1,INDEX(('Kalem Kataloğu'!$A$1:$A$1000=A39)*('Kalem Kataloğu'!$B$1:$B$1000=E39),0),0)),"?") | G39: =IFERROR(INDEX('Kalem Kataloğu'!$D$1:$D$1000,MATCH(1,INDEX(('Kalem Kataloğu'!$A$1:$A$1000=A39)*('Kalem Kataloğu'!$B$1:$B$1000=E39),0),0)),"?") | I39: Hayır | J39: Drive foto (Tem. 2024) | K39: Sadece X4 Exclusive Suite. [güven: yüksek]
A40: Tare Houses Hotel | B40: X1 | D40: =IFERROR(INDEX('Kontrol Adımları'!$D:$D,MATCH(1,INDEX(('Kontrol Adımları'!$A$1:$A$400=B40)*('Kontrol Adımları'!$B$1:$B$400=C40),0),0)),"") | E40: desk_with_chair | F40: =IFERROR(INDEX('Kalem Kataloğu'!$C$1:$C$1000,MATCH(1,INDEX(('Kalem Kataloğu'!$A$1:$A$1000=A40)*('Kalem Kataloğu'!$B$1:$B$1000=E40),0),0)),"?") | G40: =IFERROR(INDEX('Kalem Kataloğu'!$D$1:$D$1000,MATCH(1,INDEX(('Kalem Kataloğu'!$A$1:$A$1000=A40)*('Kalem Kataloğu'!$B$1:$B$1000=E40),0),0)),"?") | H40: 1 | I40: Hayır | J40: Drive foto (Tem. 2024) | K40: X1: oturma alanında çalışma masası + berjer. X2: kapı yanında konsol masa. [güven: orta]
A41: Tare Houses Hotel | B41: X1 | D41: =IFERROR(INDEX('Kontrol Adımları'!$D:$D,MATCH(1,INDEX(('Kontrol Adımları'!$A$1:$A$400=B41)*('Kontrol Adımları'!$B$1:$B$400=C41),0),0)),"") | E41: bed | F41: =IFERROR(INDEX('Kalem Kataloğu'!$C$1:$C$1000,MATCH(1,INDEX(('Kalem Kataloğu'!$A$1:$A$1000=A41)*('Kalem Kataloğu'!$B$1:$B$1000=E41),0),0)),"?") | G41: =IFERROR(INDEX('Kalem Kataloğu'!$D$1:$D$1000,MATCH(1,INDEX(('Kalem Kataloğu'!$A$1:$A$1000=A41)*('Kalem Kataloğu'!$B$1:$B$1000=E41),0),0)),"?") | H41: 1 | I41: Hayır | J41: Drive foto (Tem. 2024) | K41: X1 ve X2'de aynı model. X4'te yuvarlak yatak (ayrı kalem). [güven: yüksek]
A42: Tare Houses Hotel | B42: X2 | D42: =IFERROR(INDEX('Kontrol Adımları'!$D:$D,MATCH(1,INDEX(('Kontrol Adımları'!$A$1:$A$400=B42)*('Kontrol Adımları'!$B$1:$B$400=C42),0),0)),"") | E42: cooktop | F42: =IFERROR(INDEX('Kalem Kataloğu'!$C$1:$C$1000,MATCH(1,INDEX(('Kalem Kataloğu'!$A$1:$A$1000=A42)*('Kalem Kataloğu'!$B$1:$B$1000=E42),0),0)),"?") | G42: =IFERROR(INDEX('Kalem Kataloğu'!$D$1:$D$1000,MATCH(1,INDEX(('Kalem Kataloğu'!$A$1:$A$1000=A42)*('Kalem Kataloğu'!$B$1:$B$1000=E42),0),0)),"?") | H42: 1 | I42: Hayır | J42: Drive foto (Tem. 2024) | K42: [güven: yüksek]
A43: Tare Houses Hotel | B43: X2 | D43: =IFERROR(INDEX('Kontrol Adımları'!$D:$D,MATCH(1,INDEX(('Kontrol Adımları'!$A$1:$A$400=B43)*('Kontrol Adımları'!$B$1:$B$400=C43),0),0)),"") | E43: wc | F43: =IFERROR(INDEX('Kalem Kataloğu'!$C$1:$C$1000,MATCH(1,INDEX(('Kalem Kataloğu'!$A$1:$A$1000=A43)*('Kalem Kataloğu'!$B$1:$B$1000=E43),0),0)),"?") | G43: =IFERROR(INDEX('Kalem Kataloğu'!$D$1:$D$1000,MATCH(1,INDEX(('Kalem Kataloğu'!$A$1:$A$1000=A43)*('Kalem Kataloğu'!$B$1:$B$1000=E43),0),0)),"?") | H43: 1 | I43: Hayır | J43: Drive foto (Tem. 2024) | K43: [güven: yüksek]
A44: Tare Houses Hotel | B44: X2 | D44: =IFERROR(INDEX('Kontrol Adımları'!$D:$D,MATCH(1,INDEX(('Kontrol Adımları'!$A$1:$A$400=B44)*('Kontrol Adımları'!$B$1:$B$400=C44),0),0)),"") | E44: hanging_bin | F44: =IFERROR(INDEX('Kalem Kataloğu'!$C$1:$C$1000,MATCH(1,INDEX(('Kalem Kataloğu'!$A$1:$A$1000=A44)*('Kalem Kataloğu'!$B$1:$B$1000=E44),0),0)),"?") | G44: =IFERROR(INDEX('Kalem Kataloğu'!$D$1:$D$1000,MATCH(1,INDEX(('Kalem Kataloğu'!$A$1:$A$1000=A44)*('Kalem Kataloğu'!$B$1:$B$1000=E44),0),0)),"?") | H44: 1 | I44: Hayır | J44: Drive foto (Tem. 2024) | K44: [güven: yüksek]
A45: Tare Houses Hotel | B45: X2 | D45: =IFERROR(INDEX('Kontrol Adımları'!$D:$D,MATCH(1,INDEX(('Kontrol Adımları'!$A$1:$A$400=B45)*('Kontrol Adımları'!$B$1:$B$400=C45),0),0)),"") | E45: bath_bin | F45: =IFERROR(INDEX('Kalem Kataloğu'!$C$1:$C$1000,MATCH(1,INDEX(('Kalem Kataloğu'!$A$1:$A$1000=A45)*('Kalem Kataloğu'!$B$1:$B$1000=E45),0),0)),"?") | G45: =IFERROR(INDEX('Kalem Kataloğu'!$D$1:$D$1000,MATCH(1,INDEX(('Kalem Kataloğu'!$A$1:$A$1000=A45)*('Kalem Kataloğu'!$B$1:$B$1000=E45),0),0)),"?") | H45: 1 | I45: Hayır | J45: Drive foto (Tem. 2024) | K45: Excel X3: banyo çöp kovası 1. [güven: yüksek]
A46: Tare Houses Hotel | B46: X2 | D46: =IFERROR(INDEX('Kontrol Adımları'!$D:$D,MATCH(1,INDEX(('Kontrol Adımları'!$A$1:$A$400=B46)*('Kontrol Adımları'!$B$1:$B$400=C46),0),0)),"") | E46: bedside_wall_lamp | F46: =IFERROR(INDEX('Kalem Kataloğu'!$C$1:$C$1000,MATCH(1,INDEX(('Kalem Kataloğu'!$A$1:$A$1000=A46)*('Kalem Kataloğu'!$B$1:$B$1000=E46),0),0)),"?") | G46: =IFERROR(INDEX('Kalem Kataloğu'!$D$1:$D$1000,MATCH(1,INDEX(('Kalem Kataloğu'!$A$1:$A$1000=A46)*('Kalem Kataloğu'!$B$1:$B$1000=E46),0),0)),"?") | H46: 2 | I46: Hayır | J46: Drive foto (Tem. 2024) | K46: Yatağın iki yanında. [güven: orta]
A47: Tare Houses Hotel | B47: X2 | D47: =IFERROR(INDEX('Kontrol Adımları'!$D:$D,MATCH(1,INDEX(('Kontrol Adımları'!$A$1:$A$400=B47)*('Kontrol Adımları'!$B$1:$B$400=C47),0),0)),"") | E47: range_hood | F47: =IFERROR(INDEX('Kalem Kataloğu'!$C$1:$C$1000,MATCH(1,INDEX(('Kalem Kataloğu'!$A$1:$A$1000=A47)*('Kalem Kataloğu'!$B$1:$B$1000=E47),0),0)),"?") | G47: =IFERROR(INDEX('Kalem Kataloğu'!$D$1:$D$1000,MATCH(1,INDEX(('Kalem Kataloğu'!$A$1:$A$1000=A47)*('Kalem Kataloğu'!$B$1:$B$1000=E47),0),0)),"?") | H47: 1 | I47: Hayır | J47: Drive foto (Tem. 2024) | K47: [güven: orta]
A48: Tare Houses Hotel | B48: X2 | D48: =IFERROR(INDEX('Kontrol Adımları'!$D:$D,MATCH(1,INDEX(('Kontrol Adımları'!$A$1:$A$400=B48)*('Kontrol Adımları'!$B$1:$B$400=C48),0),0)),"") | E48: decor_branches | F48: =IFERROR(INDEX('Kalem Kataloğu'!$C$1:$C$1000,MATCH(1,INDEX(('Kalem Kataloğu'!$A$1:$A$1000=A48)*('Kalem Kataloğu'!$B$1:$B$1000=E48),0),0)),"?") | G48: =IFERROR(INDEX('Kalem Kataloğu'!$D$1:$D$1000,MATCH(1,INDEX(('Kalem Kataloğu'!$A$1:$A$1000=A48)*('Kalem Kataloğu'!$B$1:$B$1000=E48),0),0)),"?") | H48: 1 | I48: Hayır | J48: Drive foto (Tem. 2024) | K48: [güven: orta]
A49: Tare Houses Hotel | B49: X2 | D49: =IFERROR(INDEX('Kontrol Adımları'!$D:$D,MATCH(1,INDEX(('Kontrol Adımları'!$A$1:$A$400=B49)*('Kontrol Adımları'!$B$1:$B$400=C49),0),0)),"") | E49: smoke_detector | F49: =IFERROR(INDEX('Kalem Kataloğu'!$C$1:$C$1000,MATCH(1,INDEX(('Kalem Kataloğu'!$A$1:$A$1000=A49)*('Kalem Kataloğu'!$B$1:$B$1000=E49),0),0)),"?") | G49: =IFERROR(INDEX('Kalem Kataloğu'!$D$1:$D$1000,MATCH(1,INDEX(('Kalem Kataloğu'!$A$1:$A$1000=A49)*('Kalem Kataloğu'!$B$1:$B$1000=E49),0),0)),"?") | H49: 1 | I49: Hayır | J49: Drive foto (Tem. 2024) | K49: [güven: orta]
...

Sheet Envanter - Mutfak
A1: Tesis | B1: Oda Tipi Kodu | C1: Adım No | D1: Adım Adı (otomatik) | E1: Kalem Kodu | F1: Kalem Adı (otomatik) | G1: Tür (otomatik) | H1: Olması Gereken Adet | I1: Doğrulandı mı | J1: Kaynak | K1: Not
A2: Tare Houses Hotel | B2: X1 | D2: =IFERROR(INDEX('Kontrol Adımları'!$D:$D,MATCH(1,INDEX(('Kontrol Adımları'!$A$1:$A$400=B2)*('Kontrol Adımları'!$B$1:$B$400=C2),0),0)),"") | E2: wooden_bowl | F2: =IFERROR(INDEX('Kalem Kataloğu'!$C$1:$C$1000,MATCH(1,INDEX(('Kalem Kataloğu'!$A$1:$A$1000=A2)*('Kalem Kataloğu'!$B$1:$B$1000=E2),0),0)),"?") | G2: =IFERROR(INDEX('Kalem Kataloğu'!$D$1:$D$1000,MATCH(1,INDEX(('Kalem Kataloğu'!$A$1:$A$1000=A2)*('Kalem Kataloğu'!$B$1:$B$1000=E2),0),0)),"?") | H2: 1 | I2: Hayır | J2: X3 ile aynı varsayıldı | K2: Mutfak seti Tare Houses tiplerinde ortak görünüyor (Drive Mutfak Gereçleri). Odada say.
A3: Tare Houses Hotel | B3: X1 | D3: =IFERROR(INDEX('Kontrol Adımları'!$D:$D,MATCH(1,INDEX(('Kontrol Adımları'!$A$1:$A$400=B3)*('Kontrol Adımları'!$B$1:$B$400=C3),0),0)),"") | E3: dish_rack | F3: =IFERROR(INDEX('Kalem Kataloğu'!$C$1:$C$1000,MATCH(1,INDEX(('Kalem Kataloğu'!$A$1:$A$1000=A3)*('Kalem Kataloğu'!$B$1:$B$1000=E3),0),0)),"?") | G3: =IFERROR(INDEX('Kalem Kataloğu'!$D$1:$D$1000,MATCH(1,INDEX(('Kalem Kataloğu'!$A$1:$A$1000=A3)*('Kalem Kataloğu'!$B$1:$B$1000=E3),0),0)),"?") | H3: 1 | I3: Hayır | J3: Drive foto (Tem. 2024) | K3: [güven: yüksek]
A4: Tare Houses Hotel | B4: X1 | D4: =IFERROR(INDEX('Kontrol Adımları'!$D:$D,MATCH(1,INDEX(('Kontrol Adımları'!$A$1:$A$400=B4)*('Kontrol Adımları'!$B$1:$B$400=C4),0),0)),"") | E4: dinner_plate | F4: =IFERROR(INDEX('Kalem Kataloğu'!$C$1:$C$1000,MATCH(1,INDEX(('Kalem Kataloğu'!$A$1:$A$1000=A4)*('Kalem Kataloğu'!$B$1:$B$1000=E4),0),0)),"?") | G4: =IFERROR(INDEX('Kalem Kataloğu'!$D$1:$D$1000,MATCH(1,INDEX(('Kalem Kataloğu'!$A$1:$A$1000=A4)*('Kalem Kataloğu'!$B$1:$B$1000=E4),0),0)),"?") | H4: 4 | I4: Hayır | J4: Drive foto (Tem. 2024) | K4: Dolapta 4'lü yığın. Excel X3: "Büyük tabak (gri)" 4 → uyumlu. Mutfak Gereçleri klasörü oda numarası belirtmiyor (Temmuz 2024 çekimi); tüm TH tiplerinde aynı mutfak seti olduğu varsayıldı, X3 değeri 18.10.2026 videosundan. [güven: orta]
A5: Tare Houses Hotel | B5: X1 | D5: =IFERROR(INDEX('Kontrol Adımları'!$D:$D,MATCH(1,INDEX(('Kontrol Adımları'!$A$1:$A$400=B5)*('Kontrol Adımları'!$B$1:$B$400=C5),0),0)),"") | E5: sponge_caddy | F5: =IFERROR(INDEX('Kalem Kataloğu'!$C$1:$C$1000,MATCH(1,INDEX(('Kalem Kataloğu'!$A$1:$A$1000=A5)*('Kalem Kataloğu'!$B$1:$B$1000=E5),0),0)),"?") | G5: =IFERROR(INDEX('Kalem Kataloğu'!$D$1:$D$1000,MATCH(1,INDEX(('Kalem Kataloğu'!$A$1:$A$1000=A5)*('Kalem Kataloğu'!$B$1:$B$1000=E5),0),0)),"?") | H5: 1 | I5: Hayır | J5: Drive foto (Tem. 2024) | K5: Excel X3: fırça+sünger+deterjan standı 1. Sünger sarf. [güven: yüksek]
A6: Tare Houses Hotel | B6: X1 | D6: =IFERROR(INDEX('Kontrol Adımları'!$D:$D,MATCH(1,INDEX(('Kontrol Adımları'!$A$1:$A$400=B6)*('Kontrol Adımları'!$B$1:$B$400=C6),0),0)),"") | E6: bowl | F6: =IFERROR(INDEX('Kalem Kataloğu'!$C$1:$C$1000,MATCH(1,INDEX(('Kalem Kataloğu'!$A$1:$A$1000=A6)*('Kalem Kataloğu'!$B$1:$B$1000=E6),0),0)),"?") | G6: =IFERROR(INDEX('Kalem Kataloğu'!$D$1:$D$1000,MATCH(1,INDEX(('Kalem Kataloğu'!$A$1:$A$1000=A6)*('Kalem Kataloğu'!$B$1:$B$1000=E6),0),0)),"?") | H6: 4 | I6: Hayır | J6: Drive foto (Tem. 2024) | K6: Dolapta 4'lü yığın. Excel X3 "Kase (yeşil)" 4 → uyumlu (renk farkı algısal). Mutfak Gereçleri klasörü oda numarası belirtmiyor (Temmuz 2024 çekimi); tüm TH tiplerinde aynı mutfak seti olduğu varsayıldı, X3 değeri 18.10.2026 videosundan. [güven: orta]
A7: Tare Houses Hotel | B7: X1 | D7: =IFERROR(INDEX('Kontrol Adımları'!$D:$D,MATCH(1,INDEX(('Kontrol Adımları'!$A$1:$A$400=B7)*('Kontrol Adımları'!$B$1:$B$400=C7),0),0)),"") | E7: cutting_board | F7: =IFERROR(INDEX('Kalem Kataloğu'!$C$1:$C$1000,MATCH(1,INDEX(('Kalem Kataloğu'!$A$1:$A$1000=A7)*('Kalem Kataloğu'!$B$1:$B$1000=E7),0),0)),"?") | G7: =IFERROR(INDEX('Kalem Kataloğu'!$D$1:$D$1000,MATCH(1,INDEX(('Kalem Kataloğu'!$A$1:$A$1000=A7)*('Kalem Kataloğu'!$B$1:$B$1000=E7),0),0)),"?") | H7: 1 | I7: Hayır | J7: Drive foto (Tem. 2024) | K7: Bıçak seti kutusunun altında. Excel X3: kesme tahtası 1. [güven: orta]
A8: Tare Houses Hotel | B8: X1 | D8: =IFERROR(INDEX('Kontrol Adımları'!$D:$D,MATCH(1,INDEX(('Kontrol Adımları'!$A$1:$A$400=B8)*('Kontrol Adımları'!$B$1:$B$400=C8),0),0)),"") | E8: knife_set | F8: =IFERROR(INDEX('Kalem Kataloğu'!$C$1:$C$1000,MATCH(1,INDEX(('Kalem Kataloğu'!$A$1:$A$1000=A8)*('Kalem Kataloğu'!$B$1:$B$1000=E8),0),0)),"?") | G8: =IFERROR(INDEX('Kalem Kataloğu'!$D$1:$D$1000,MATCH(1,INDEX(('Kalem Kataloğu'!$A$1:$A$1000=A8)*('Kalem Kataloğu'!$B$1:$B$1000=E8),0),0)),"?") | H8: 1 | I8: Hayır | J8: Drive foto (Tem. 2024) | K8: Excel X3: Kiyomi bıçak seti 1. Kutu içi 7 parça tam mı kontrol edilmeli. Mutfak Gereçleri klasörü oda numarası belirtmiyor (Temmuz 2024 çekimi); tüm TH tiplerinde aynı mutfak seti olduğu varsayıldı, X3 değeri 18.10.2026 videosundan. [güven: yüksek]
A9: Tare Houses Hotel | B9: X1 | D9: =IFERROR(INDEX('Kontrol Adımları'!$D:$D,MATCH(1,INDEX(('Kontrol Adımları'!$A$1:$A$400=B9)*('Kontrol Adımları'!$B$1:$B$400=C9),0),0)),"") | E9: saucepan | F9: =IFERROR(INDEX('Kalem Kataloğu'!$C$1:$C$1000,MATCH(1,INDEX(('Kalem Kataloğu'!$A$1:$A$1000=A9)*('Kalem Kataloğu'!$B$1:$B$1000=E9),0),0)),"?") | G9: =IFERROR(INDEX('Kalem Kataloğu'!$D$1:$D$1000,MATCH(1,INDEX(('Kalem Kataloğu'!$A$1:$A$1000=A9)*('Kalem Kataloğu'!$B$1:$B$1000=E9),0),0)),"?") | H9: 1 | I9: Hayır | J9: X3 ile aynı varsayıldı | K9: Mutfak seti Tare Houses tiplerinde ortak görünüyor (Drive Mutfak Gereçleri). Odada say.
A10: Tare Houses Hotel | B10: X1 | D10: =IFERROR(INDEX('Kontrol Adımları'!$D:$D,MATCH(1,INDEX(('Kontrol Adımları'!$A$1:$A$400=B10)*('Kontrol Adımları'!$B$1:$B$400=C10),0),0)),"") | E10: mug | F10: =IFERROR(INDEX('Kalem Kataloğu'!$C$1:$C$1000,MATCH(1,INDEX(('Kalem Kataloğu'!$A$1:$A$1000=A10)*('Kalem Kataloğu'!$B$1:$B$1000=E10),0),0)),"?") | G10: =IFERROR(INDEX('Kalem Kataloğu'!$D$1:$D$1000,MATCH(1,INDEX(('Kalem Kataloğu'!$A$1:$A$1000=A10)*('Kalem Kataloğu'!$B$1:$B$1000=E10),0),0)),"?") | H10: 2 | I10: Hayır | J10: X3 ile aynı varsayıldı | K10: Mutfak seti Tare Houses tiplerinde ortak görünüyor (Drive Mutfak Gereçleri). Odada say.
A11: Tare Houses Hotel | B11: X1 | D11: =IFERROR(INDEX('Kontrol Adımları'!$D:$D,MATCH(1,INDEX(('Kontrol Adımları'!$A$1:$A$400=B11)*('Kontrol Adımları'!$B$1:$B$400=C11),0),0)),"") | E11: side_plate | F11: =IFERROR(INDEX('Kalem Kataloğu'!$C$1:$C$1000,MATCH(1,INDEX(('Kalem Kataloğu'!$A$1:$A$1000=A11)*('Kalem Kataloğu'!$B$1:$B$1000=E11),0),0)),"?") | G11: =IFERROR(INDEX('Kalem Kataloğu'!$D$1:$D$1000,MATCH(1,INDEX(('Kalem Kataloğu'!$A$1:$A$1000=A11)*('Kalem Kataloğu'!$B$1:$B$1000=E11),0),0)),"?") | H11: 4 | I11: Hayır | J11: Drive foto (Tem. 2024) | K11: Dolapta 4'lü yığın. Excel X3: "Küçük tabak (gri)" 4 → uyumlu. Mutfak Gereçleri klasörü oda numarası belirtmiyor (Temmuz 2024 çekimi); tüm TH tiplerinde aynı mutfak seti olduğu varsayıldı, X3 değeri 18.10.2026 videosundan. [güven: orta]
